Workbook

Sheet 1-Blade sections
A1: Instructions for the Users:
A2: Insert your values
A3: 1. Copy paste your values of local radius, chord length and twist angle from Excel file attached to Assignment 4 'Adjust blade geometry_Fall26' (cells A to C)
A4: 2. Copy the relative coordinates (i.e. x/c and y/c) in the designated columns (cells J and K)
A5: 3. If the number of coordinates for your airfoil is more than the table marked below, extend the columns named 'Translated x/c', 'Translated y/c', 'Section 2' and so on upto the same number of rows as your coordinates
A7: What's going on in the sheet?
A8: 1. The cylinder/airfoil profile has been translated to locate the center of the airfoil chord at the origin (cells (J,k) and (O,P))
A9: 2. Airfoil/cylinder has been scaled up by the factor of the chord length/diameter, transformed to [mm], and the coordinates are now rotated about the origin by the respective twist angle (from cell R on)
A10: 3. The coordinates are put together, along with the Z coordinate, which is the local radius, separated by commas (in next sheet "3-Data to be imported to Fusion"). Those are the data you will import to Fusion360 when you will start with your CAD design
E12: Section 1: cylinder | J12: Other sections: airfoil | O12: Section1 (cylinder) | R12: Section 2 | U12: Section 3 | X12: Section 4 | AA12: Section 5 | AD12: Section 6 | AG12: Section 7 | AJ12: Section 8 | AM12: Section 9 | AP12: Section 10 | AS12: Section 11 | AV12: Section 12 | AY12: Section 13 | BB12: Section 14 | BE12: Section 15 | BH12: Section 16 | BK12: Section 17 | BN12: Section 18 | BQ12: Section 18 | BT12: Section 18
A13: local radius [m] | B13: chord length [m] | C13: Twist [deg] | E13: x/c | F13: y/c | G13: Translated x/c | H13: Translated y/c | J13: x/c | K13: y/c | L13: Translated x/c | M13: Translated y/c | O13: X1 | P13: Y1 | R13: X2 | S13: Y2 | U13: X3 | V13: Y3 | X13: X4 | Y13: Y4 | AA13: X5 | AB13: Y5 | AD13: X6 | AE13: Y6 | AG13: X7 | AH13: Y7 | AJ13: X8 | AK13: Y8 | AM13: X9 | AN13: Y9 | AP13: X10 | AQ13: Y10 | AS13: X11 | AT13: Y11 | AV13: X12 | AW13: Y12 | AY13: X13 | AZ13: Y13 | BB13: X14 | BC13: Y14 | BE13: X15 | BF13: Y15 | BH13: X16 | BI13: Y16 | BK13: X17 | BL13: Y17 | BN13: X18 | BO13: Y18 | BQ13: X19 | BR13: Y19 | BT13: X20 | BU13: Y20
A14: 0.03 | B14: 0.048 | C14: 0 | E14: 1 | F14: 0 | G14: =E14-(MIN($E$14:$E$46)+MAX($J$14:$J$48))/2 -> 0.49939 | H14: =F14-(INDEX($F$14:$F$48,MATCH(MIN($E$14:$E$48),$E$14:$E$48,0))+INDEX($F$14:$F$48,MATCH(MAX($E$14:$E$48),$E$14:$E$48,0)))/2 -> -0.01744 | J14: 1 | K14: 0.0016 | L14: =J14-(MIN($J$14:$J$48)+MAX($J$14:$J$48))/2 -> 0.5 | M14: =K14-(INDEX($K$14:$K$48,MATCH(MIN($J$14:$J$48),$J$14:$J$48,0))+INDEX($K$14:$K$48,MATCH(MAX($J$14:$J$48),$J$14:$J$48,0)))/2 -> 0.0008 | O14: =(G14*COS(RADIANS($C$14))-H14*SIN(RADIANS($C$14)))*$B$14*1000 -> 23.97072 | P14: =(G14*SIN(RADIANS($C$14))+H14*COS(RADIANS($C$14)))*$B$14*1000 -> -0.83712 | R14: =(L14*COS(RADIANS($C$15))-M14*SIN(RADIANS($C$15)))*$B$15*1000 -> 92.560497 | S14: =(L14*SIN(RADIANS($C$15))+M14*COS(RADIANS($C$15)))*$B$15*1000 -> 53.718696 | U14: =(L14*COS(RADIANS($C$16))-M14*SIN(RADIANS($C$16)))*$B$16*1000 -> 89.423649 | V14: =(L14*SIN(RADIANS($C$16))+M14*COS(RADIANS($C$16)))*$B$16*1000 -> 33.395412 | X14: =(L14*COS(RADIANS($C$17))-M14*SIN(RADIANS($C$17)))*$B$17*1000 -> 76.920717 | Y14: =(L14*SIN(RADIANS($C$17))+M14*COS(RADIANS($C$17)))*$B$17*1000 -> 20.009353 | AA14: =(L14*COS(RADIANS($C$18))-M14*SIN(RADIANS($C$18)))*$B$18*1000 -> 65.311129 | AB14: =(L14*SIN(RADIANS($C$18))+M14*COS(RADIANS($C$18)))*$B$18*1000 -> 12.427885 | AD14: =(L14*COS(RADIANS($C$19))-M14*SIN(RADIANS($C$19)))*$B$19*1000 -> 56.02042 | AE14: =(L14*SIN(RADIANS($C$19))+M14*COS(RADIANS($C$19)))*$B$19*1000 -> 8.0333557 | AG14: =(L14*COS(RADIANS($C$20))-M14*SIN(RADIANS($C$20)))*$B$20*1000 -> 48.7462 | AH14: =(L14*SIN(RADIANS($C$20))+M14*COS(RADIANS($C$20)))*$B$20*1000 -> 5.3575973 | AJ14: =(L14*COS(RADIANS($C$21))-M14*SIN(RADIANS($C$21)))*$B$21*1000 -> 43.004248 | AK14: =(L14*SIN(RADIANS($C$21))+M14*COS(RADIANS($C$21)))*$B$21*1000 -> 3.6489095 | AM14: =(L14*COS(RADIANS($C$22))-M14*SIN(RADIANS($C$22)))*$B$22*1000 -> 38.400035 | AN14: =(L14*SIN(RADIANS($C$22))+M14*COS(RADIANS($C$22)))*$B$22*1000 -> 2.5122907 | AP14: =(L14*COS(RADIANS($C$23))-M14*SIN(RADIANS($C$23)))*$B$23*1000 -> 34.645878 | AQ14: =(L14*SIN(RADIANS($C$23))+M14*COS(RADIANS($C$23)))*$B$23*1000 -> 1.7301076 | AS14: =(L14*COS(RADIANS($C$24))-M14*SIN(RADIANS($C$24)))*$B$24*1000 -> 34.645878 | AT14: =(L14*SIN(RADIANS($C$24))+M14*COS(RADIANS($C$24)))*$B$24*1000 -> 1.7301076 | AV14: =(L14*COS(RADIANS($C$25))-M14*SIN(RADIANS($C$25)))*$B$25*1000 -> 0 | AW14: =(L14*SIN(RADIANS($C$25))+M14*COS(RADIANS($C$25)))*$B$25*1000 -> 0 | AY14: =(L14*COS(RADIANS($C$26))-M14*SIN(RADIANS($C$26)))*$B$26*1000 -> 0 | AZ14: =(L14*SIN(RADIANS($C$26))+M14*COS(RADIANS($C$26)))*$B$26*1000 -> 0 | BB14: =(L14*COS(RADIANS($C$27))-M14*SIN(RADIANS($C$27)))*$B$27*1000 -> 0 | BC14: =(L14*SIN(RADIANS($C$27))+M14*COS(RADIANS($C$27)))*$B$27*1000 -> 0 | BE14: =(L14*COS(RADIANS($C$28))-M14*SIN(RADIANS($C$28)))*$B$28*1000 -> 0 | BF14: =(L14*SIN(RADIANS($C$28))+M14*COS(RADIANS($C$28)))*$B$28*1000 -> 0 | BH14: =(L14*COS(RADIANS($C$29))-M14*SIN(RADIANS($C$29)))*$B$29*1000 -> 0 | BI14: =(L14*SIN(RADIANS($C$29))+M14*COS(RADIANS($C$29)))*$B$29*1000 -> 0 | BK14: =(L14*COS(RADIANS($C$30))-M14*SIN(RADIANS($C$30)))*$B$30*1000 -> 0 | BL14: =(L14*SIN(RADIANS($C$30))+M14*COS(RADIANS($C$30)))*$B$30*1000 -> 0 | BN14: =(L14*COS(RADIANS($C$31))-M14*SIN(RADIANS($C$31)))*$B$31*1000 -> 0 | BO14: =(L14*SIN(RADIANS($C$31))+M14*COS(RADIANS($C$31)))*$B$31*1000 -> 0 | BQ14: =(L14*COS(RADIANS($C$32))-M14*SIN(RADIANS($C$32)))*$B$32*1000 -> 0 | BR14: =(L14*SIN(RADIANS($C$32))+M14*COS(RADIANS($C$32)))*$B$32*1000 -> 0 | BT14: =(L14*COS(RADIANS($C$33))-M14*SIN(RADIANS($C$33)))*$B$33*1000 -> 0 | BU14: =(L14*SIN(RADIANS($C$33))+M14*COS(RADIANS($C$33)))*$B$33*1000 -> 0
A15: 0.0675 | B15: 0.21403845 | C15: 30.037624 | E15: 0.99081 | F15: 0.0954 | G15: =E15-(MIN($E$14:$E$46)+MAX($J$14:$J$48))/2 -> 0.4902 | H15: =F15-(INDEX($F$14:$F$48,MATCH(MIN($E$14:$E$48),$E$14:$E$48,0))+INDEX($F$14:$F$48,MATCH(MAX($E$14:$E$48),$E$14:$E$48,0)))/2 -> 0.07796 | J15: 0.95 | K15: 0.0112 | L15: =J15-(MIN($J$14:$J$48)+MAX($J$14:$J$48))/2 -> 0.45 | M15: =K15-(INDEX($K$14:$K$48,MATCH(MIN($J$14:$J$48),$J$14:$J$48,0))+INDEX($K$14:$K$48,MATCH(MAX($J$14:$J$48),$J$14:$J$48,0)))/2 -> 0.0104 | O15: =(G15*COS(RADIANS($C$14))-H15*SIN(RADIANS($C$14)))*$B$14*1000 -> 23.5296 | P15: =(G15*SIN(RADIANS($C$14))+H15*COS(RADIANS($C$14)))*$B$14*1000 -> 3.74208 | R15: =(L15*COS(RADIANS($C$15))-M15*SIN(RADIANS($C$15)))*$B$15*1000 -> 82.267323 | S15: =(L15*SIN(RADIANS($C$15))+M15*COS(RADIANS($C$15)))*$B$15*1000 -> 50.140457 | U15: =(L15*COS(RADIANS($C$16))-M15*SIN(RADIANS($C$16)))*$B$16*1000 -> 79.837521 | V15: =(L15*SIN(RADIANS($C$16))+M15*COS(RADIANS($C$16)))*$B$16*1000 -> 31.788143 | X15: =(L15*COS(RADIANS($C$17))-M15*SIN(RADIANS($C$17)))*$B$17*1000 -> 68.843647 | Y15: =(L15*SIN(RADIANS($C$17))+M15*COS(RADIANS($C$17)))*$B$17*1000 -> 19.498218 | AA15: =(L15*COS(RADIANS($C$18))-M15*SIN(RADIANS($C$18)))*$B$18*1000 -> 58.541436 | AB15: =(L15*SIN(RADIANS($C$18))+M15*COS(RADIANS($C$18)))*$B$18*1000 -> 12.449902 | AD15: =(L15*COS(RADIANS($C$19))-M15*SIN(RADIANS($C$19)))*$B$19*1000 -> 50.264588 | AE15: =(L15*SIN(RADIANS($C$19))+M15*COS(RADIANS($C$19)))*$B$19*1000 -> 8.3148215 | AG15: =(L15*COS(RADIANS($C$20))-M15*SIN(RADIANS($C$20)))*$B$20*1000 -> 43.769367 | AH15: =(L15*SIN(RADIANS($C$20))+M15*COS(RADIANS($C$20)))*$B$20*1000 -> 5.7657276 | AJ15: =(L15*COS(RADIANS($C$21))-M15*SIN(RADIANS($C$21)))*$B$21*1000 -> 38.634513 | AK15: =(L15*SIN(RADIANS($C$21))+M15*COS(RADIANS($C$21)))*$B$21*1000 -> 4.1166917 | AM15: =(L15*COS(RADIANS($C$22))-M15*SIN(RADIANS($C$22)))*$B$22*1000 -> 34.512583 | AN15: =(L15*SIN(RADIANS($C$22))+M15*COS(RADIANS($C$22)))*$B$22*1000 -> 3.0045622 | AP15: =(L15*COS(RADIANS($C$23))-M15*SIN(RADIANS($C$23)))*$B$23*1000 -> 31.148869 | AQ15: =(L15*SIN(RADIANS($C$23))+M15*COS(RADIANS($C$23)))*$B$23*1000 -> 2.2278929 | AS15: =(L15*COS(RADIANS($C$24))-M15*SIN(RADIANS($C$24)))*$B$24*1000 -> 31.148869 | AT15: =(L15*SIN(RADIANS($C$24))+M15*COS(RADIANS($C$24)))*$B$24*1000 -> 2.2278929 | AV15: =(L15*COS(RADIANS($C$25))-M15*SIN(RADIANS($C$25)))*$B$25*1000 -> 0 | AW15: =(L15*SIN(RADIANS($C$25))+M15*COS(RADIANS($C$25)))*$B$25*1000 -> 0 | AY15: =(L15*COS(RADIANS($C$26))-M15*SIN(RADIANS($C$26)))*$B$26*1000 -> 0 | AZ15: =(L15*SIN(RADIANS($C$26))+M15*COS(RADIANS($C$26)))*$B$26*1000 -> 0 | BB15: =(L15*COS(RADIANS($C$27))-M15*SIN(RADIANS($C$27)))*$B$27*1000 -> 0 | BC15: =(L15*SIN(RADIANS($C$27))+M15*COS(RADIANS($C$27)))*$B$27*1000 -> 0 | BE15: =(L15*COS(RADIANS($C$28))-M15*SIN(RADIANS($C$28)))*$B$28*1000 -> 0 | BF15: =(L15*SIN(RADIANS($C$28))+M15*COS(RADIANS($C$28)))*$B$28*1000 -> 0 | BH15: =(L15*COS(RADIANS($C$29))-M15*SIN(RADIANS($C$29)))*$B$29*1000 -> 0 | BI15: =(L15*SIN(RADIANS($C$29))+M15*COS(RADIANS($C$29)))*$B$29*1000 -> 0 | BK15: =(L15*COS(RADIANS($C$30))-M15*SIN(RADIANS($C$30)))*$B$30*1000 -> 0 | BL15: =(L15*SIN(RADIANS($C$30))+M15*COS(RADIANS($C$30)))*$B$30*1000 -> 0 | BN15: =(L15*COS(RADIANS($C$31))-M15*SIN(RADIANS($C$31)))*$B$31*1000 -> 0 | BO15: =(L15*SIN(RADIANS($C$31))+M15*COS(RADIANS($C$31)))*$B$31*1000 -> 0 | BQ15: =(L15*COS(RADIANS($C$32))-M15*SIN(RADIANS($C$32)))*$B$32*1000 -> 0 | BR15: =(L15*SIN(RADIANS($C$32))+M15*COS(RADIANS($C$32)))*$B$32*1000 -> 0 | BT15: =(L15*COS(RADIANS($C$33))-M15*SIN(RADIANS($C$33)))*$B$33*1000 -> 0 | BU15: =(L15*SIN(RADIANS($C$33))+M15*COS(RADIANS($C$33)))*$B$33*1000 -> 0
A16: 0.1125 | B16: 0.1909117 | C16: 20.386558 | E16: 0.96359 | F16: 0.1873 | G16: =E16-(MIN($E$14:$E$46)+MAX($J$14:$J$48))/2 -> 0.46298 | H16: =F16-(INDEX($F$14:$F$48,MATCH(MIN($E$14:$E$48),$E$14:$E$48,0))+INDEX($F$14:$F$48,MATCH(MAX($E$14:$E$48),$E$14:$E$48,0)))/2 -> 0.16986 | J16: 0.9 | K16: 0.0204 | L16: =J16-(MIN($J$14:$J$48)+MAX($J$14:$J$48))/2 -> 0.4 | M16: =K16-(INDEX($K$14:$K$48,MATCH(MIN($J$14:$J$48),$J$14:$J$48,0))+INDEX($K$14:$K$48,MATCH(MAX($J$14:$J$48),$J$14:$J$48,0)))/2 -> 0.0196 | O16: =(G16*COS(RADIANS($C$14))-H16*SIN(RADIANS($C$14)))*$B$14*1000 -> 22.22304 | P16: =(G16*SIN(RADIANS($C$14))+H16*COS(RADIANS($C$14)))*$B$14*1000 -> 8.15328 | R16: =(L16*COS(RADIANS($C$15))-M16*SIN(RADIANS($C$15)))*$B$15*1000 -> 72.017006 | S16: =(L16*SIN(RADIANS($C$15))+M16*COS(RADIANS($C$15)))*$B$15*1000 -> 46.488101 | U16: =(L16*COS(RADIANS($C$16))-M16*SIN(RADIANS($C$16)))*$B$16*1000 -> 70.277994 | V16: =(L16*SIN(RADIANS($C$16))+M16*COS(RADIANS($C$16)))*$B$16*1000 -> 30.109292 | X16: =(L16*COS(RADIANS($C$17))-M16*SIN(RADIANS($C$17)))*$B$17*1000 -> 60.782487 | Y16: =(L16*SIN(RADIANS($C$17))+M16*COS(RADIANS($C$17)))*$B$17*1000 -> 18.925522 | AA16: =(L16*COS(RADIANS($C$18))-M16*SIN(RADIANS($C$18)))*$B$18*1000 -> 51.781602 | AB16: =(L16*SIN(RADIANS($C$18))+M16*COS(RADIANS($C$18)))*$B$18*1000 -> 12.419654 | AD16: =(L16*COS(RADIANS($C$19))-M16*SIN(RADIANS($C$19)))*$B$19*1000 -> 44.515111 | AE16: =(L16*SIN(RADIANS($C$19))+M16*COS(RADIANS($C$19)))*$B$19*1000 -> 8.5514609 | AG16: =(L16*COS(RADIANS($C$20))-M16*SIN(RADIANS($C$20)))*$B$20*1000 -> 38.796758 | AH16: =(L16*SIN(RADIANS($C$20))+M16*COS(RADIANS($C$20)))*$B$20*1000 -> 6.1348541 | AJ16: =(L16*COS(RADIANS($C$21))-M16*SIN(RADIANS($C$21)))*$B$21*1000 -> 34.267641 | AK16: =(L16*SIN(RADIANS($C$21))+M16*COS(RADIANS($C$21)))*$B$21*1000 -> 4.5500659 | AM16: =(L16*COS(RADIANS($C$22))-M16*SIN(RADIANS($C$22)))*$B$22*1000 -> 30.627092 | AN16: =(L16*SIN(RADIANS($C$22))+M16*COS(RADIANS($C$22)))*$B$22*1000 -> 3.4661106 | AP16: =(L16*COS(RADIANS($C$23))-M16*SIN(RADIANS($C$23)))*$B$23*1000 -> 27.653199 | AQ16: =(L16*SIN(RADIANS($C$23))+M16*COS(RADIANS($C$23)))*$B$23*1000 -> 2.6979594 | AS16: =(L16*COS(RADIANS($C$24))-M16*SIN(RADIANS($C$24)))*$B$24*1000 -> 27.653199 | AT16: =(L16*SIN(RADIANS($C$24))+M16*COS(RADIANS($C$24)))*$B$24*1000 -> 2.6979594 | AV16: =(L16*COS(RADIANS($C$25))-M16*SIN(RADIANS($C$25)))*$B$25*1000 -> 0 | AW16: =(L16*SIN(RADIANS($C$25))+M16*COS(RADIANS($C$25)))*$B$25*1000 -> 0 | AY16: =(L16*COS(RADIANS($C$26))-M16*SIN(RADIANS($C$26)))*$B$26*1000 -> 0 | AZ16: =(L16*SIN(RADIANS($C$26))+M16*COS(RADIANS($C$26)))*$B$26*1000 -> 0 | BB16: =(L16*COS(RADIANS($C$27))-M16*SIN(RADIANS($C$27)))*$B$27*1000 -> 0 | BC16: =(L16*SIN(RADIANS($C$27))+M16*COS(RADIANS($C$27)))*$B$27*1000 -> 0 | BE16: =(L16*COS(RADIANS($C$28))-M16*SIN(RADIANS($C$28)))*$B$28*1000 -> 0 | BF16: =(L16*SIN(RADIANS($C$28))+M16*COS(RADIANS($C$28)))*$B$28*1000 -> 0 | BH16: =(L16*COS(RADIANS($C$29))-M16*SIN(RADIANS($C$29)))*$B$29*1000 -> 0 | BI16: =(L16*SIN(RADIANS($C$29))+M16*COS(RADIANS($C$29)))*$B$29*1000 -> 0 | BK16: =(L16*COS(RADIANS($C$30))-M16*SIN(RADIANS($C$30)))*$B$30*1000 -> 0 | BL16: =(L16*SIN(RADIANS($C$30))+M16*COS(RADIANS($C$30)))*$B$30*1000 -> 0 | BN16: =(L16*COS(RADIANS($C$31))-M16*SIN(RADIANS($C$31)))*$B$31*1000 -> 0 | BO16: =(L16*SIN(RADIANS($C$31))+M16*COS(RADIANS($C$31)))*$B$31*1000 -> 0 | BQ16: =(L16*COS(RADIANS($C$32))-M16*SIN(RADIANS($C$32)))*$B$32*1000 -> 0 | BR16: =(L16*SIN(RADIANS($C$32))+M16*COS(RADIANS($C$32)))*$B$32*1000 -> 0 | BT16: =(L16*COS(RADIANS($C$33))-M16*SIN(RADIANS($C$33)))*$B$33*1000 -> 0 | BU16: =(L16*SIN(RADIANS($C$33))+M16*COS(RADIANS($C$33)))*$B$33*1000 -> 0
A17: 0.1575 | B17: 0.15896106 | C17: 14.489496 | E17: 0.91934 | F17: 0.27232 | G17: =E17-(MIN($E$14:$E$46)+MAX($J$14:$J$48))/2 -> 0.41873 | H17: =F17-(INDEX($F$14:$F$48,MATCH(MIN($E$14:$E$48),$E$14:$E$48,0))+INDEX($F$14:$F$48,MATCH(MAX($E$14:$E$48),$E$14:$E$48,0)))/2 -> 0.25488 | J17: 0.8 | K17: 0.0373 | L17: =J17-(MIN($J$14:$J$48)+MAX($J$14:$J$48))/2 -> 0.3 | M17: =K17-(INDEX($K$14:$K$48,MATCH(MIN($J$14:$J$48),$J$14:$J$48,0))+INDEX($K$14:$K$48,MATCH(MAX($J$14:$J$48),$J$14:$J$48,0)))/2 -> 0.0365 | O17: =(G17*COS(RADIANS($C$14))-H17*SIN(RADIANS($C$14)))*$B$14*1000 -> 20.09904 | P17: =(G17*SIN(RADIANS($C$14))+H17*COS(RADIANS($C$14)))*$B$14*1000 -> 12.23424 | R17: =(L17*COS(RADIANS($C$15))-M17*SIN(RADIANS($C$15)))*$B$15*1000 -> 51.677082 | S17: =(L17*SIN(RADIANS($C$15))+M17*COS(RADIANS($C$15)))*$B$15*1000 -> 38.90545 | U17: =(L17*COS(RADIANS($C$16))-M17*SIN(RADIANS($C$16)))*$B$16*1000 -> 51.258698 | V17: =(L17*SIN(RADIANS($C$16))+M17*COS(RADIANS($C$16)))*$B$16*1000 -> 26.48316 | X17: =(L17*COS(RADIANS($C$17))-M17*SIN(RADIANS($C$17)))*$B$17*1000 -> 44.719826 | Y17: =(L17*SIN(RADIANS($C$17))+M17*COS(RADIANS($C$17)))*$B$17*1000 -> 17.549272 | AA17: =(L17*COS(RADIANS($C$18))-M17*SIN(RADIANS($C$18)))*$B$18*1000 -> 38.298903 | AB17: =(L17*SIN(RADIANS($C$18))+M17*COS(RADIANS($C$18)))*$B$18*1000 -> 12.163165 | AD17: =(L17*COS(RADIANS($C$19))-M17*SIN(RADIANS($C$19)))*$B$19*1000 -> 33.039988 | AE17: =(L17*SIN(RADIANS($C$19))+M17*COS(RADIANS($C$19)))*$B$19*1000 -> 8.8566401 | AG17: =(L17*COS(RADIANS($C$20))-M17*SIN(RADIANS($C$20)))*$B$20*1000 -> 28.867378 | AH17: =(L17*SIN(RADIANS($C$20))+M17*COS(RADIANS($C$20)))*$B$20*1000 -> 6.7268432 | AJ17: =(L17*COS(RADIANS($C$21))-M17*SIN(RADIANS($C$21)))*$B$21*1000 -> 25.544639 | AK17: =(L17*SIN(RADIANS($C$21))+M17*COS(RADIANS($C$21)))*$B$21*1000 -> 5.2877844 | AM17: =(L17*COS(RADIANS($C$22))-M17*SIN(RADIANS($C$22)))*$B$22*1000 -> 22.863462 | AN17: =(L17*SIN(RADIANS($C$22))+M17*COS(RADIANS($C$22)))*$B$22*1000 -> 4.2739954 | AP17: =(L17*COS(RADIANS($C$23))-M17*SIN(RADIANS($C$23)))*$B$23*1000 -> 20.666884 | AQ17: =(L17*SIN(RADIANS($C$23))+M17*COS(RADIANS($C$23)))*$B$23*1000 -> 3.5341466 | AS17: =(L17*COS(RADIANS($C$24))-M17*SIN(RADIANS($C$24)))*$B$24*1000 -> 20.666884 | AT17: =(L17*SIN(RADIANS($C$24))+M17*COS(RADIANS($C$24)))*$B$24*1000 -> 3.5341466 | AV17: =(L17*COS(RADIANS($C$25))-M17*SIN(RADIANS($C$25)))*$B$25*1000 -> 0 | AW17: =(L17*SIN(RADIANS($C$25))+M17*COS(RADIANS($C$25)))*$B$25*1000 -> 0 | AY17: =(L17*COS(RADIANS($C$26))-M17*SIN(RADIANS($C$26)))*$B$26*1000 -> 0 | AZ17: =(L17*SIN(RADIANS($C$26))+M17*COS(RADIANS($C$26)))*$B$26*1000 -> 0 | BB17: =(L17*COS(RADIANS($C$27))-M17*SIN(RADIANS($C$27)))*$B$27*1000 -> 0 | BC17: =(L17*SIN(RADIANS($C$27))+M17*COS(RADIANS($C$27)))*$B$27*1000 -> 0 | BE17: =(L17*COS(RADIANS($C$28))-M17*SIN(RADIANS($C$28)))*$B$28*1000 -> 0 | BF17: =(L17*SIN(RADIANS($C$28))+M17*COS(RADIANS($C$28)))*$B$28*1000 -> 0 | BH17: =(L17*COS(RADIANS($C$29))-M17*SIN(RADIANS($C$29)))*$B$29*1000 -> 0 | BI17: =(L17*SIN(RADIANS($C$29))+M17*COS(RADIANS($C$29)))*$B$29*1000 -> 0 | BK17: =(L17*COS(RADIANS($C$30))-M17*SIN(RADIANS($C$30)))*$B$30*1000 -> 0 | BL17: =(L17*SIN(RADIANS($C$30))+M17*COS(RADIANS($C$30)))*$B$30*1000 -> 0 | BN17: =(L17*COS(RADIANS($C$31))-M17*SIN(RADIANS($C$31)))*$B$31*1000 -> 0 | BO17: =(L17*SIN(RADIANS($C$31))+M17*COS(RADIANS($C$31)))*$B$31*1000 -> 0 | BQ17: =(L17*COS(RADIANS($C$32))-M17*SIN(RADIANS($C$32)))*$B$32*1000 -> 0 | BR17: =(L17*SIN(RADIANS($C$32))+M17*COS(RADIANS($C$32)))*$B$32*1000 -> 0 | BT17: =(L17*COS(RADIANS($C$33))-M17*SIN(RADIANS($C$33)))*$B$33*1000 -> 0 | BU17: =(L17*SIN(RADIANS($C$33))+M17*COS(RADIANS($C$33)))*$B$33*1000 -> 0
A18: 0.2025 | B18: 0.13296593 | C18: 10.682186 | E18: 0.85967 | F18: 0.34733 | G18: =E18-(MIN($E$14:$E$46)+MAX($J$14:$J$48))/2 -> 0.35906 | H18: =F18-(INDEX($F$14:$F$48,MATCH(MIN($E$14:$E$48),$E$14:$E$48,0))+INDEX($F$14:$F$48,MATCH(MAX($E$14:$E$48),$E$14:$E$48,0)))/2 -> 0.32989 | J18: 0.7 | K18: 0.0525 | L18: =J18-(MIN($J$14:$J$48)+MAX($J$14:$J$48))/2 -> 0.2 | M18: =K18-(INDEX($K$14:$K$48,MATCH(MIN($J$14:$J$48),$J$14:$J$48,0))+INDEX($K$14:$K$48,MATCH(MAX($J$14:$J$48),$J$14:$J$48,0)))/2 -> 0.0517 | O18: =(G18*COS(RADIANS($C$14))-H18*SIN(RADIANS($C$14)))*$B$14*1000 -> 17.23488 | P18: =(G18*SIN(RADIANS($C$14))+H18*COS(RADIANS($C$14)))*$B$14*1000 -> 15.83472 | R18: =(L18*COS(RADIANS($C$15))-M18*SIN(RADIANS($C$15)))*$B$15*1000 -> 31.519298 | S18: =(L18*SIN(RADIANS($C$15))+M18*COS(RADIANS($C$15)))*$B$15*1000 -> 31.007803 | U18: =(L18*COS(RADIANS($C$16))-M18*SIN(RADIANS($C$16)))*$B$16*1000 -> 32.352459 | V18: =(L18*SIN(RADIANS($C$16))+M18*COS(RADIANS($C$16)))*$B$16*1000 -> 22.552806 | X18: =(L18*COS(RADIANS($C$17))-M18*SIN(RADIANS($C$17)))*$B$17*1000 -> 28.724778 | Y18: =(L18*SIN(RADIANS($C$17))+M18*COS(RADIANS($C$17)))*$B$17*1000 -> 15.911383 | AA18: =(L18*COS(RADIANS($C$18))-M18*SIN(RADIANS($C$18)))*$B$18*1000 -> 24.858104 | AB18: =(L18*SIN(RADIANS($C$18))+M18*COS(RADIANS($C$18)))*$B$18*1000 -> 11.684552 | AD18: =(L18*COS(RADIANS($C$19))-M18*SIN(RADIANS($C$19)))*$B$19*1000 -> 21.591873 | AE18: =(L18*SIN(RADIANS($C$19))+M18*COS(RADIANS($C$19)))*$B$19*1000 -> 8.9713067 | AG18: =(L18*COS(RADIANS($C$20))-M18*SIN(RADIANS($C$20)))*$B$20*1000 -> 18.955949 | AH18: =(L18*SIN(RADIANS($C$20))+M18*COS(RADIANS($C$20)))*$B$20*1000 -> 7.1530665 | AJ18: =(L18*COS(RADIANS($C$21))-M18*SIN(RADIANS($C$21)))*$B$21*1000 -> 16.833809 | AK18: =(L18*SIN(RADIANS($C$21))+M18*COS(RADIANS($C$21)))*$B$21*1000 -> 5.8792689 | AM18: =(L18*COS(RADIANS($C$22))-M18*SIN(RADIANS($C$22)))*$B$22*1000 -> 15.108165 | AN18: =(L18*SIN(RADIANS($C$22))+M18*COS(RADIANS($C$22)))*$B$22*1000 -> 4.9513068 | AP18: =(L18*COS(RADIANS($C$23))-M18*SIN(RADIANS($C$23)))*$B$23*1000 -> 13.686262 | AQ18: =(L18*SIN(RADIANS($C$23))+M18*COS(RADIANS($C$23)))*$B$23*1000 -> 4.2525288 | AS18: =(L18*COS(RADIANS($C$24))-M18*SIN(RADIANS($C$24)))*$B$24*1000 -> 13.686262 | AT18: =(L18*SIN(RADIANS($C$24))+M18*COS(RADIANS($C$24)))*$B$24*1000 -> 4.2525288 | AV18: =(L18*COS(RADIANS($C$25))-M18*SIN(RADIANS($C$25)))*$B$25*1000 -> 0 | AW18: =(L18*SIN(RADIANS($C$25))+M18*COS(RADIANS($C$25)))*$B$25*1000 -> 0 | AY18: =(L18*COS(RADIANS($C$26))-M18*SIN(RADIANS($C$26)))*$B$26*1000 -> 0 | AZ18: =(L18*SIN(RADIANS($C$26))+M18*COS(RADIANS($C$26)))*$B$26*1000 -> 0 | BB18: =(L18*COS(RADIANS($C$27))-M18*SIN(RADIANS($C$27)))*$B$27*1000 -> 0 | BC18: =(L18*SIN(RADIANS($C$27))+M18*COS(RADIANS($C$27)))*$B$27*1000 -> 0 | BE18: =(L18*COS(RADIANS($C$28))-M18*SIN(RADIANS($C$28)))*$B$28*1000 -> 0 | BF18: =(L18*SIN(RADIANS($C$28))+M18*COS(RADIANS($C$28)))*$B$28*1000 -> 0 | BH18: =(L18*COS(RADIANS($C$29))-M18*SIN(RADIANS($C$29)))*$B$29*1000 -> 0 | BI18: =(L18*SIN(RADIANS($C$29))+M18*COS(RADIANS($C$29)))*$B$29*1000 -> 0 | BK18: =(L18*COS(RADIANS($C$30))-M18*SIN(RADIANS($C$30)))*$B$30*1000 -> 0 | BL18: =(L18*SIN(RADIANS($C$30))+M18*COS(RADIANS($C$30)))*$B$30*1000 -> 0 | BN18: =(L18*COS(RADIANS($C$31))-M18*SIN(RADIANS($C$31)))*$B$31*1000 -> 0 | BO18: =(L18*SIN(RADIANS($C$31))+M18*COS(RADIANS($C$31)))*$B$31*1000 -> 0 | BQ18: =(L18*COS(RADIANS($C$32))-M18*SIN(RADIANS($C$32)))*$B$32*1000 -> 0 | BR18: =(L18*SIN(RADIANS($C$32))+M18*COS(RADIANS($C$32)))*$B$32*1000 -> 0 | BT18: =(L18*COS(RADIANS($C$33))-M18*SIN(RADIANS($C$33)))*$B$33*1000 -> 0 | BU18: =(L18*SIN(RADIANS($C$33))+M18*COS(RADIANS($C$33)))*$B$33*1000 -> 0
A19: 0.2475 | B19: 0.11318682 | C19: 8.0689358 | E19: 0.78679 | F19: 0.40958 | G19: =E19-(MIN($E$14:$E$46)+MAX($J$14:$J$48))/2 -> 0.28618 | H19: =F19-(INDEX($F$14:$F$48,MATCH(MIN($E$14:$E$48),$E$14:$E$48,0))+INDEX($F$14:$F$48,MATCH(MAX($E$14:$E$48),$E$14:$E$48,0)))/2 -> 0.39214 | J19: 0.6 | K19: 0.0661 | L19: =J19-(MIN($J$14:$J$48)+MAX($J$14:$J$48))/2 -> 0.1 | M19: =K19-(INDEX($K$14:$K$48,MATCH(MIN($J$14:$J$48),$J$14:$J$48,0))+INDEX($K$14:$K$48,MATCH(MAX($J$14:$J$48),$J$14:$J$48,0)))/2 -> 0.0653 | O19: =(G19*COS(RADIANS($C$14))-H19*SIN(RADIANS($C$14)))*$B$14*1000 -> 13.73664 | P19: =(G19*SIN(RADIANS($C$14))+H19*COS(RADIANS($C$14)))*$B$14*1000 -> 18.82272 | R19: =(L19*COS(RADIANS($C$15))-M19*SIN(RADIANS($C$15)))*$B$15*1000 -> 11.53294 | S19: =(L19*SIN(RADIANS($C$15))+M19*COS(RADIANS($C$15)))*$B$15*1000 -> 22.813687 | U19: =(L19*COS(RADIANS($C$16))-M19*SIN(RADIANS($C$16)))*$B$16*1000 -> 13.552627 | V19: =(L19*SIN(RADIANS($C$16))+M19*COS(RADIANS($C$16)))*$B$16*1000 -> 18.336127 | X19: =(L19*COS(RADIANS($C$17))-M19*SIN(RADIANS($C$17)))*$B$17*1000 -> 12.793365 | Y19: =(L19*SIN(RADIANS($C$17))+M19*COS(RADIANS($C$17)))*$B$17*1000 -> 14.027247 | AA19: =(L19*COS(RADIANS($C$18))-M19*SIN(RADIANS($C$18)))*$B$18*1000 -> 11.456739 | AB19: =(L19*SIN(RADIANS($C$18))+M19*COS(RADIANS($C$18)))*$B$18*1000 -> 10.99688 | AD19: =(L19*COS(RADIANS($C$19))-M19*SIN(RADIANS($C$19)))*$B$19*1000 -> 10.169178 | AE19: =(L19*SIN(RADIANS($C$19))+M19*COS(RADIANS($C$19)))*$B$19*1000 -> 8.9066673 | AG19: =(L19*COS(RADIANS($C$20))-M19*SIN(RADIANS($C$20)))*$B$20*1000 -> 9.0614151 | AH19: =(L19*SIN(RADIANS($C$20))+M19*COS(RADIANS($C$20)))*$B$20*1000 -> 7.4232749 | AJ19: =(L19*COS(RADIANS($C$21))-M19*SIN(RADIANS($C$21)))*$B$21*1000 -> 8.134435 | AK19: =(L19*SIN(RADIANS($C$21))+M19*COS(RADIANS($C$21)))*$B$21*1000 -> 6.3331216 | AM19: =(L19*COS(RADIANS($C$22))-M19*SIN(RADIANS($C$22)))*$B$22*1000 -> 7.3607109 | AN19: =(L19*SIN(RADIANS($C$22))+M19*COS(RADIANS($C$22)))*$B$22*1000 -> 5.5057255 | AP19: =(L19*COS(RADIANS($C$23))-M19*SIN(RADIANS($C$23)))*$B$23*1000 -> 6.7109996 | AQ19: =(L19*SIN(RADIANS($C$23))+M19*COS(RADIANS($C$23)))*$B$23*1000 -> 4.8600356 | AS19: =(L19*COS(RADIANS($C$24))-M19*SIN(RADIANS($C$24)))*$B$24*1000 -> 6.7109996 | AT19: =(L19*SIN(RADIANS($C$24))+M19*COS(RADIANS($C$24)))*$B$24*1000 -> 4.8600356 | AV19: =(L19*COS(RADIANS($C$25))-M19*SIN(RADIANS($C$25)))*$B$25*1000 -> 0 | AW19: =(L19*SIN(RADIANS($C$25))+M19*COS(RADIANS($C$25)))*$B$25*1000 -> 0 | AY19: =(L19*COS(RADIANS($C$26))-M19*SIN(RADIANS($C$26)))*$B$26*1000 -> 0 | AZ19: =(L19*SIN(RADIANS($C$26))+M19*COS(RADIANS($C$26)))*$B$26*1000 -> 0 | BB19: =(L19*COS(RADIANS($C$27))-M19*SIN(RADIANS($C$27)))*$B$27*1000 -> 0 | BC19: =(L19*SIN(RADIANS($C$27))+M19*COS(RADIANS($C$27)))*$B$27*1000 -> 0 | BE19: =(L19*COS(RADIANS($C$28))-M19*SIN(RADIANS($C$28)))*$B$28*1000 -> 0 | BF19: =(L19*SIN(RADIANS($C$28))+M19*COS(RADIANS($C$28)))*$B$28*1000 -> 0 | BH19: =(L19*COS(RADIANS($C$29))-M19*SIN(RADIANS($C$29)))*$B$29*1000 -> 0 | BI19: =(L19*SIN(RADIANS($C$29))+M19*COS(RADIANS($C$29)))*$B$29*1000 -> 0 | BK19: =(L19*COS(RADIANS($C$30))-M19*SIN(RADIANS($C$30)))*$B$30*1000 -> 0 | BL19: =(L19*SIN(RADIANS($C$30))+M19*COS(RADIANS($C$30)))*$B$30*1000 -> 0 | BN19: =(L19*COS(RADIANS($C$31))-M19*SIN(RADIANS($C$31)))*$B$31*1000 -> 0 | BO19: =(L19*SIN(RADIANS($C$31))+M19*COS(RADIANS($C$31)))*$B$31*1000 -> 0 | BQ19: =(L19*COS(RADIANS($C$32))-M19*SIN(RADIANS($C$32)))*$B$32*1000 -> 0 | BR19: =(L19*SIN(RADIANS($C$32))+M19*COS(RADIANS($C$32)))*$B$32*1000 -> 0 | BT19: =(L19*COS(RADIANS($C$33))-M19*SIN(RADIANS($C$33)))*$B$33*1000 -> 0 | BU19: =(L19*SIN(RADIANS($C$33))+M19*COS(RADIANS($C$33)))*$B$33*1000 -> 0
A20: 0.2925 | B20: 0.09807935 | C20: 6.180417 | E20: 0.70337 | F20: 0.45677 | G20: =E20-(MIN($E$14:$E$46)+MAX($J$14:$J$48))/2 -> 0.20276 | H20: =F20-(INDEX($F$14:$F$48,MATCH(MIN($E$14:$E$48),$E$14:$E$48,0))+INDEX($F$14:$F$48,MATCH(MAX($E$14:$E$48),$E$14:$E$48,0)))/2 -> 0.43933 | J20: 0.5 | K20: 0.0774 | L20: =J20-(MIN($J$14:$J$48)+MAX($J$14:$J$48))/2 -> 0 | M20: =K20-(INDEX($K$14:$K$48,MATCH(MIN($J$14:$J$48),$J$14:$J$48,0))+INDEX($K$14:$K$48,MATCH(MAX($J$14:$J$48),$J$14:$J$48,0)))/2 -> 0.0766 | O20: =(G20*COS(RADIANS($C$14))-H20*SIN(RADIANS($C$14)))*$B$14*1000 -> 9.73248 | P20: =(G20*SIN(RADIANS($C$14))+H20*COS(RADIANS($C$14)))*$B$14*1000 -> 21.08784 | R20: =(L20*COS(RADIANS($C$15))-M20*SIN(RADIANS($C$15)))*$B$15*1000 -> -8.2069947 | S20: =(L20*SIN(RADIANS($C$15))+M20*COS(RADIANS($C$15)))*$B$15*1000 -> 14.193399 | U20: =(L20*COS(RADIANS($C$16))-M20*SIN(RADIANS($C$16)))*$B$16*1000 -> -5.0942446 | V20: =(L20*SIN(RADIANS($C$16))+M20*COS(RADIANS($C$16)))*$B$16*1000 -> 13.707854 | X20: =(L20*COS(RADIANS($C$17))-M20*SIN(RADIANS($C$17)))*$B$17*1000 -> -3.0465702 | Y20: =(L20*SIN(RADIANS($C$17))+M20*COS(RADIANS($C$17)))*$B$17*1000 -> 11.789128 | AA20: =(L20*COS(RADIANS($C$18))-M20*SIN(RADIANS($C$18)))*$B$18*1000 -> -1.8879381 | AB20: =(L20*SIN(RADIANS($C$18))+M20*COS(RADIANS($C$18)))*$B$18*1000 -> 10.008686 | AD20: =(L20*COS(RADIANS($C$19))-M20*SIN(RADIANS($C$19)))*$B$19*1000 -> -1.2169753 | AE20: =(L20*SIN(RADIANS($C$19))+M20*COS(RADIANS($C$19)))*$B$19*1000 -> 8.5842755 | AG20: =(L20*COS(RADIANS($C$20))-M20*SIN(RADIANS($C$20)))*$B$20*1000 -> -0.80883317 | AH20: =(L20*SIN(RADIANS($C$20))+M20*COS(RADIANS($C$20)))*$B$20*1000 -> 7.469212 | AJ20: =(L20*COS(RADIANS($C$21))-M20*SIN(RADIANS($C$21)))*$B$21*1000 -> -0.54847033 | AK20: =(L20*SIN(RADIANS($C$21))+M20*COS(RADIANS($C$21)))*$B$21*1000 -> 6.5891283 | AM20: =(L20*COS(RADIANS($C$22))-M20*SIN(RADIANS($C$22)))*$B$22*1000 -> -0.37546936 | AN20: =(L20*SIN(RADIANS($C$22))+M20*COS(RADIANS($C$22)))*$B$22*1000 -> 5.8834861 | AP20: =(L20*COS(RADIANS($C$23))-M20*SIN(RADIANS($C$23)))*$B$23*1000 -> -0.25655943 | AQ20: =(L20*SIN(RADIANS($C$23))+M20*COS(RADIANS($C$23)))*$B$23*1000 -> 5.308159 | AS20: =(L20*COS(RADIANS($C$24))-M20*SIN(RADIANS($C$24)))*$B$24*1000 -> -0.25655943 | AT20: =(L20*SIN(RADIANS($C$24))+M20*COS(RADIANS($C$24)))*$B$24*1000 -> 5.308159 | AV20: =(L20*COS(RADIANS($C$25))-M20*SIN(RADIANS($C$25)))*$B$25*1000 -> 0 | AW20: =(L20*SIN(RADIANS($C$25))+M20*COS(RADIANS($C$25)))*$B$25*1000 -> 0 | AY20: =(L20*COS(RADIANS($C$26))-M20*SIN(RADIANS($C$26)))*$B$26*1000 -> 0 | AZ20: =(L20*SIN(RADIANS($C$26))+M20*COS(RADIANS($C$26)))*$B$26*1000 -> 0 | BB20: =(L20*COS(RADIANS($C$27))-M20*SIN(RADIANS($C$27)))*$B$27*1000 -> 0 | BC20: =(L20*SIN(RADIANS($C$27))+M20*COS(RADIANS($C$27)))*$B$27*1000 -> 0 | BE20: =(L20*COS(RADIANS($C$28))-M20*SIN(RADIANS($C$28)))*$B$28*1000 -> 0 | BF20: =(L20*SIN(RADIANS($C$28))+M20*COS(RADIANS($C$28)))*$B$28*1000 -> 0 | BH20: =(L20*COS(RADIANS($C$29))-M20*SIN(RADIANS($C$29)))*$B$29*1000 -> 0 | BI20: =(L20*SIN(RADIANS($C$29))+M20*COS(RADIANS($C$29)))*$B$29*1000 -> 0 | BK20: =(L20*COS(RADIANS($C$30))-M20*SIN(RADIANS($C$30)))*$B$30*1000 -> 0 | BL20: =(L20*SIN(RADIANS($C$30))+M20*COS(RADIANS($C$30)))*$B$30*1000 -> 0 | BN20: =(L20*COS(RADIANS($C$31))-M20*SIN(RADIANS($C$31)))*$B$31*1000 -> 0 | BO20: =(L20*SIN(RADIANS($C$31))+M20*COS(RADIANS($C$31)))*$B$31*1000 -> 0 | BQ20: =(L20*COS(RADIANS($C$32))-M20*SIN(RADIANS($C$32)))*$B$32*1000 -> 0 | BR20: =(L20*SIN(RADIANS($C$32))+M20*COS(RADIANS($C$32)))*$B$32*1000 -> 0 | BT20: =(L20*COS(RADIANS($C$33))-M20*SIN(RADIANS($C$33)))*$B$33*1000 -> 0 | BU20: =(L20*SIN(RADIANS($C$33))+M20*COS(RADIANS($C$33)))*$B$33*1000 -> 0
A21: 0.3375 | B21: 0.08631744 | C21: 4.7582557 | E21: 0.61248 | F21: 0.48719 | G21: =E21-(MIN($E$14:$E$46)+MAX($J$14:$J$48))/2 -> 0.11187 | H21: =F21-(INDEX($F$14:$F$48,MATCH(MIN($E$14:$E$48),$E$14:$E$48,0))+INDEX($F$14:$F$48,MATCH(MAX($E$14:$E$48),$E$14:$E$48,0)))/2 -> 0.46975 | J21: 0.4 | K21: 0.0859 | L21: =J21-(MIN($J$14:$J$48)+MAX($J$14:$J$48))/2 -> -0.1 | M21: =K21-(INDEX($K$14:$K$48,MATCH(MIN($J$14:$J$48),$J$14:$J$48,0))+INDEX($K$14:$K$48,MATCH(MAX($J$14:$J$48),$J$14:$J$48,0)))/2 -> 0.0851 | O21: =(G21*COS(RADIANS($C$14))-H21*SIN(RADIANS($C$14)))*$B$14*1000 -> 5.36976 | P21: =(G21*SIN(RADIANS($C$14))+H21*COS(RADIANS($C$14)))*$B$14*1000 -> 22.548 | R21: =(L21*COS(RADIANS($C$15))-M21*SIN(RADIANS($C$15)))*$B$15*1000 -> -27.646935 | S21: =(L21*SIN(RADIANS($C$15))+M21*COS(RADIANS($C$15)))*$B$15*1000 -> 5.0542925 | U21: =(L21*COS(RADIANS($C$16))-M21*SIN(RADIANS($C$16)))*$B$16*1000 -> -23.554903 | V21: =(L21*SIN(RADIANS($C$16))+M21*COS(RADIANS($C$16)))*$B$16*1000 -> 8.5785105 | X21: =(L21*COS(RADIANS($C$17))-M21*SIN(RADIANS($C$17)))*$B$17*1000 -> -18.775143 | Y21: =(L21*SIN(RADIANS($C$17))+M21*COS(RADIANS($C$17)))*$B$17*1000 -> 9.1200757 | AA21: =(L21*COS(RADIANS($C$18))-M21*SIN(RADIANS($C$18)))*$B$18*1000 -> -15.163604 | AB21: =(L21*SIN(RADIANS($C$18))+M21*COS(RADIANS($C$18)))*$B$18*1000 -> 8.654639 | AD21: =(L21*COS(RADIANS($C$19))-M21*SIN(RADIANS($C$19)))*$B$19*1000 -> -12.558644 | AE21: =(L21*SIN(RADIANS($C$19))+M21*COS(RADIANS($C$19)))*$B$19*1000 -> 7.9480982 | AG21: =(L21*COS(RADIANS($C$20))-M21*SIN(RADIANS($C$20)))*$B$20*1000 -> -10.649516 | AH21: =(L21*SIN(RADIANS($C$20))+M21*COS(RADIANS($C$20)))*$B$20*1000 -> 7.242123 | AJ21: =(L21*COS(RADIANS($C$21))-M21*SIN(RADIANS($C$21)))*$B$21*1000 -> -9.2113271 | AK21: =(L21*SIN(RADIANS($C$21))+M21*COS(RADIANS($C$21)))*$B$21*1000 -> 6.6042792 | AM21: =(L21*COS(RADIANS($C$22))-M21*SIN(RADIANS($C$22)))*$B$22*1000 -> -8.0979249 | AN21: =(L21*SIN(RADIANS($C$22))+M21*COS(RADIANS($C$22)))*$B$22*1000 -> 6.0461844 | AP21: =(L21*COS(RADIANS($C$23))-M21*SIN(RADIANS($C$23)))*$B$23*1000 -> -7.2147403 | AQ21: =(L21*SIN(RADIANS($C$23))+M21*COS(RADIANS($C$23)))*$B$23*1000 -> 5.5622505 | AS21: =(L21*COS(RADIANS($C$24))-M21*SIN(RADIANS($C$24)))*$B$24*1000 -> -7.2147403 | AT21: =(L21*SIN(RADIANS($C$24))+M21*COS(RADIANS($C$24)))*$B$24*1000 -> 5.5622505 | AV21: =(L21*COS(RADIANS($C$25))-M21*SIN(RADIANS($C$25)))*$B$25*1000 -> 0 | AW21: =(L21*SIN(RADIANS($C$25))+M21*COS(RADIANS($C$25)))*$B$25*1000 -> 0 | AY21: =(L21*COS(RADIANS($C$26))-M21*SIN(RADIANS($C$26)))*$B$26*1000 -> 0 | AZ21: =(L21*SIN(RADIANS($C$26))+M21*COS(RADIANS($C$26)))*$B$26*1000 -> 0 | BB21: =(L21*COS(RADIANS($C$27))-M21*SIN(RADIANS($C$27)))*$B$27*1000 -> 0 | BC21: =(L21*SIN(RADIANS($C$27))+M21*COS(RADIANS($C$27)))*$B$27*1000 -> 0 | BE21: =(L21*COS(RADIANS($C$28))-M21*SIN(RADIANS($C$28)))*$B$28*1000 -> 0 | BF21: =(L21*SIN(RADIANS($C$28))+M21*COS(RADIANS($C$28)))*$B$28*1000 -> 0 | BH21: =(L21*COS(RADIANS($C$29))-M21*SIN(RADIANS($C$29)))*$B$29*1000 -> 0 | BI21: =(L21*SIN(RADIANS($C$29))+M21*COS(RADIANS($C$29)))*$B$29*1000 -> 0 | BK21: =(L21*COS(RADIANS($C$30))-M21*SIN(RADIANS($C$30)))*$B$30*1000 -> 0 | BL21: =(L21*SIN(RADIANS($C$30))+M21*COS(RADIANS($C$30)))*$B$30*1000 -> 0 | BN21: =(L21*COS(RADIANS($C$31))-M21*SIN(RADIANS($C$31)))*$B$31*1000 -> 0 | BO21: =(L21*SIN(RADIANS($C$31))+M21*COS(RADIANS($C$31)))*$B$31*1000 -> 0 | BQ21: =(L21*COS(RADIANS($C$32))-M21*SIN(RADIANS($C$32)))*$B$32*1000 -> 0 | BR21: =(L21*SIN(RADIANS($C$32))+M21*COS(RADIANS($C$32)))*$B$32*1000 -> 0 | BT21: =(L21*COS(RADIANS($C$33))-M21*SIN(RADIANS($C$33)))*$B$33*1000 -> 0 | BU21: =(L21*SIN(RADIANS($C$33))+M21*COS(RADIANS($C$33)))*$B$33*1000 -> 0
A22: 0.3825 | B22: 0.07696416 | C22: 3.6515215 | E22: 0.51745 | F22: 0.4997 | G22: =E22-(MIN($E$14:$E$46)+MAX($J$14:$J$48))/2 -> 0.01684 | H22: =F22-(INDEX($F$14:$F$48,MATCH(MIN($E$14:$E$48),$E$14:$E$48,0))+INDEX($F$14:$F$48,MATCH(MAX($E$14:$E$48),$E$14:$E$48,0)))/2 -> 0.48226 | J22: 0.3 | K22: 0.0905 | L22: =J22-(MIN($J$14:$J$48)+MAX($J$14:$J$48))/2 -> -0.2 | M22: =K22-(INDEX($K$14:$K$48,MATCH(MIN($J$14:$J$48),$J$14:$J$48,0))+INDEX($K$14:$K$48,MATCH(MAX($J$14:$J$48),$J$14:$J$48,0)))/2 -> 0.0897 | O22: =(G22*COS(RADIANS($C$14))-H22*SIN(RADIANS($C$14)))*$B$14*1000 -> 0.80832 | P22: =(G22*SIN(RADIANS($C$14))+H22*COS(RADIANS($C$14)))*$B$14*1000 -> 23.14848 | R22: =(L22*COS(RADIANS($C$15))-M22*SIN(RADIANS($C$15)))*$B$15*1000 -> -46.669025 | S22: =(L22*SIN(RADIANS($C$15))+M22*COS(RADIANS($C$15)))*$B$15*1000 -> -4.8074547 | U22: =(L22*COS(RADIANS($C$16))-M22*SIN(RADIANS($C$16)))*$B$16*1000 -> -41.756195 | V22: =(L22*SIN(RADIANS($C$16))+M22*COS(RADIANS($C$16)))*$B$16*1000 -> 2.7512476 | X22: =(L22*COS(RADIANS($C$17))-M22*SIN(RADIANS($C$17)))*$B$17*1000 -> -34.348603 | Y22: =(L22*SIN(RADIANS($C$17))+M22*COS(RADIANS($C$17)))*$B$17*1000 -> 5.8507933 | AA22: =(L22*COS(RADIANS($C$18))-M22*SIN(RADIANS($C$18)))*$B$18*1000 -> -28.343149 | AB22: =(L22*SIN(RADIANS($C$18))+M22*COS(RADIANS($C$18)))*$B$18*1000 -> 6.7910117 | AD22: =(L22*COS(RADIANS($C$19))-M22*SIN(RADIANS($C$19)))*$B$19*1000 -> -23.838352 | AE22: =(L22*SIN(RADIANS($C$19))+M22*COS(RADIANS($C$19)))*$B$19*1000 -> 6.8748624 | AG22: =(L22*COS(RADIANS($C$20))-M22*SIN(RADIANS($C$20)))*$B$20*1000 -> -20.449017 | AH22: =(L22*SIN(RADIANS($C$20))+M22*COS(RADIANS($C$20)))*$B$20*1000 -> 6.6347478 | AJ22: =(L22*COS(RADIANS($C$21))-M22*SIN(RADIANS($C$21)))*$B$21*1000 -> -17.846259 | AK22: =(L22*SIN(RADIANS($C$21))+M22*COS(RADIANS($C$21)))*$B$21*1000 -> 6.2839523 | AM22: =(L22*COS(RADIANS($C$22))-M22*SIN(RADIANS($C$22)))*$B$22*1000 -> -15.801264 | AN22: =(L22*SIN(RADIANS($C$22))+M22*COS(RADIANS($C$22)))*$B$22*1000 -> 5.909332 | AP22: =(L22*COS(RADIANS($C$23))-M22*SIN(RADIANS($C$23)))*$B$23*1000 -> -14.159859 | AQ22: =(L22*SIN(RADIANS($C$23))+M22*COS(RADIANS($C$23)))*$B$23*1000 -> 5.5460833 | AS22: =(L22*COS(RADIANS($C$24))-M22*SIN(RADIANS($C$24)))*$B$24*1000 -> -14.159859 | AT22: =(L22*SIN(RADIANS($C$24))+M22*COS(RADIANS($C$24)))*$B$24*1000 -> 5.5460833 | AV22: =(L22*COS(RADIANS($C$25))-M22*SIN(RADIANS($C$25)))*$B$25*1000 -> 0 | AW22: =(L22*SIN(RADIANS($C$25))+M22*COS(RADIANS($C$25)))*$B$25*1000 -> 0 | AY22: =(L22*COS(RADIANS($C$26))-M22*SIN(RADIANS($C$26)))*$B$26*1000 -> 0 | AZ22: =(L22*SIN(RADIANS($C$26))+M22*COS(RADIANS($C$26)))*$B$26*1000 -> 0 | BB22: =(L22*COS(RADIANS($C$27))-M22*SIN(RADIANS($C$27)))*$B$27*1000 -> 0 | BC22: =(L22*SIN(RADIANS($C$27))+M22*COS(RADIANS($C$27)))*$B$27*1000 -> 0 | BE22: =(L22*COS(RADIANS($C$28))-M22*SIN(RADIANS($C$28)))*$B$28*1000 -> 0 | BF22: =(L22*SIN(RADIANS($C$28))+M22*COS(RADIANS($C$28)))*$B$28*1000 -> 0 | BH22: =(L22*COS(RADIANS($C$29))-M22*SIN(RADIANS($C$29)))*$B$29*1000 -> 0 | BI22: =(L22*SIN(RADIANS($C$29))+M22*COS(RADIANS($C$29)))*$B$29*1000 -> 0 | BK22: =(L22*COS(RADIANS($C$30))-M22*SIN(RADIANS($C$30)))*$B$30*1000 -> 0 | BL22: =(L22*SIN(RADIANS($C$30))+M22*COS(RADIANS($C$30)))*$B$30*1000 -> 0 | BN22: =(L22*COS(RADIANS($C$31))-M22*SIN(RADIANS($C$31)))*$B$31*1000 -> 0 | BO22: =(L22*SIN(RADIANS($C$31))+M22*COS(RADIANS($C$31)))*$B$31*1000 -> 0 | BQ22: =(L22*COS(RADIANS($C$32))-M22*SIN(RADIANS($C$32)))*$B$32*1000 -> 0 | BR22: =(L22*SIN(RADIANS($C$32))+M22*COS(RADIANS($C$32)))*$B$32*1000 -> 0 | BT22: =(L22*COS(RADIANS($C$33))-M22*SIN(RADIANS($C$33)))*$B$33*1000 -> 0 | BU22: =(L22*SIN(RADIANS($C$33))+M22*COS(RADIANS($C$33)))*$B$33*1000 -> 0
A23: 0.4275 | B23: 0.06937801 | C23: 2.7671254 | E23: 0.42178 | F23: 0.49384 | G23: =E23-(MIN($E$14:$E$46)+MAX($J$14:$J$48))/2 -> -0.07883 | H23: =F23-(INDEX($F$14:$F$48,MATCH(MIN($E$14:$E$48),$E$14:$E$48,0))+INDEX($F$14:$F$48,MATCH(MAX($E$14:$E$48),$E$14:$E$48,0)))/2 -> 0.4764 | J23: 0.25 | K23: 0.0908 | L23: =J23-(MIN($J$14:$J$48)+MAX($J$14:$J$48))/2 -> -0.25 | M23: =K23-(INDEX($K$14:$K$48,MATCH(MIN($J$14:$J$48),$J$14:$J$48,0))+INDEX($K$14:$K$48,MATCH(MAX($J$14:$J$48),$J$14:$J$48,0)))/2 -> 0.09 | O23: =(G23*COS(RADIANS($C$14))-H23*SIN(RADIANS($C$14)))*$B$14*1000 -> -3.78384 | P23: =(G23*SIN(RADIANS($C$14))+H23*COS(RADIANS($C$14)))*$B$14*1000 -> 22.8672 | R23: =(L23*COS(RADIANS($C$15))-M23*SIN(RADIANS($C$15)))*$B$15*1000 -> -55.965788 | S23: =(L23*SIN(RADIANS($C$15))+M23*COS(RADIANS($C$15)))*$B$15*1000 -> -10.108913 | U23: =(L23*COS(RADIANS($C$16))-M23*SIN(RADIANS($C$16)))*$B$16*1000 -> -50.723831 | V23: =(L23*SIN(RADIANS($C$16))+M23*COS(RADIANS($C$16)))*$B$16*1000 -> -0.52029119 | X23: =(L23*COS(RADIANS($C$17))-M23*SIN(RADIANS($C$17)))*$B$17*1000 -> -42.055788 | Y23: =(L23*SIN(RADIANS($C$17))+M23*COS(RADIANS($C$17)))*$B$17*1000 -> 3.908342 | AA23: =(L23*COS(RADIANS($C$18))-M23*SIN(RADIANS($C$18)))*$B$18*1000 -> -34.883627 | AB23: =(L23*SIN(RADIANS($C$18))+M23*COS(RADIANS($C$18)))*$B$18*1000 -> 5.5978747 | AD23: =(L23*COS(RADIANS($C$19))-M23*SIN(RADIANS($C$19)))*$B$19*1000 -> -29.446431 | AE23: =(L23*SIN(RADIANS($C$19))+M23*COS(RADIANS($C$19)))*$B$19*1000 -> 6.114112 | AG23: =(L23*COS(RADIANS($C$20))-M23*SIN(RADIANS($C$20)))*$B$20*1000 -> -25.32765 | AH23: =(L23*SIN(RADIANS($C$20))+M23*COS(RADIANS($C$20)))*$B$20*1000 -> 6.1360416 | AJ23: =(L23*COS(RADIANS($C$21))-M23*SIN(RADIANS($C$21)))*$B$21*1000 -> -22.149405 | AK23: =(L23*SIN(RADIANS($C$21))+M23*COS(RADIANS($C$21)))*$B$21*1000 -> 5.9517489 | AM23: =(L23*COS(RADIANS($C$22))-M23*SIN(RADIANS($C$22)))*$B$22*1000 -> -19.64313 | AN23: =(L23*SIN(RADIANS($C$22))+M23*COS(RADIANS($C$22)))*$B$22*1000 -> 5.6872899 | AP23: =(L23*COS(RADIANS($C$23))-M23*SIN(RADIANS($C$23)))*$B$23*1000 -> -17.625719 | AQ23: =(L23*SIN(RADIANS($C$23))+M23*COS(RADIANS($C$23)))*$B$23*1000 -> 5.3994054 | AS23: =(L23*COS(RADIANS($C$24))-M23*SIN(RADIANS($C$24)))*$B$24*1000 -> -17.625719 | AT23: =(L23*SIN(RADIANS($C$24))+M23*COS(RADIANS($C$24)))*$B$24*1000 -> 5.3994054 | AV23: =(L23*COS(RADIANS($C$25))-M23*SIN(RADIANS($C$25)))*$B$25*1000 -> 0 | AW23: =(L23*SIN(RADIANS($C$25))+M23*COS(RADIANS($C$25)))*$B$25*1000 -> 0 | AY23: =(L23*COS(RADIANS($C$26))-M23*SIN(RADIANS($C$26)))*$B$26*1000 -> 0 | AZ23: =(L23*SIN(RADIANS($C$26))+M23*COS(RADIANS($C$26)))*$B$26*1000 -> 0 | BB23: =(L23*COS(RADIANS($C$27))-M23*SIN(RADIANS($C$27)))*$B$27*1000 -> 0 | BC23: =(L23*SIN(RADIANS($C$27))+M23*COS(RADIANS($C$27)))*$B$27*1000 -> 0 | BE23: =(L23*COS(RADIANS($C$28))-M23*SIN(RADIANS($C$28)))*$B$28*1000 -> 0 | BF23: =(L23*SIN(RADIANS($C$28))+M23*COS(RADIANS($C$28)))*$B$28*1000 -> 0 | BH23: =(L23*COS(RADIANS($C$29))-M23*SIN(RADIANS($C$29)))*$B$29*1000 -> 0 | BI23: =(L23*SIN(RADIANS($C$29))+M23*COS(RADIANS($C$29)))*$B$29*1000 -> 0 | BK23: =(L23*COS(RADIANS($C$30))-M23*SIN(RADIANS($C$30)))*$B$30*1000 -> 0 | BL23: =(L23*SIN(RADIANS($C$30))+M23*COS(RADIANS($C$30)))*$B$30*1000 -> 0 | BN23: =(L23*COS(RADIANS($C$31))-M23*SIN(RADIANS($C$31)))*$B$31*1000 -> 0 | BO23: =(L23*SIN(RADIANS($C$31))+M23*COS(RADIANS($C$31)))*$B$31*1000 -> 0 | BQ23: =(L23*COS(RADIANS($C$32))-M23*SIN(RADIANS($C$32)))*$B$32*1000 -> 0 | BR23: =(L23*SIN(RADIANS($C$32))+M23*COS(RADIANS($C$32)))*$B$32*1000 -> 0 | BT23: =(L23*COS(RADIANS($C$33))-M23*SIN(RADIANS($C$33)))*$B$33*1000 -> 0 | BU23: =(L23*SIN(RADIANS($C$33))+M23*COS(RADIANS($C$33)))*$B$33*1000 -> 0
A24: 0.45 | B24: 0.06937801 | C24: 2.7671254 | E24: 0.32899 | F24: 0.46985 | G24: =E24-(MIN($E$14:$E$46)+MAX($J$14:$J$48))/2 -> -0.17162 | H24: =F24-(INDEX($F$14:$F$48,MATCH(MIN($E$14:$E$48),$E$14:$E$48,0))+INDEX($F$14:$F$48,MATCH(MAX($E$14:$E$48),$E$14:$E$48,0)))/2 -> 0.45241 | J24: 0.2 | K24: 0.0892 | L24: =J24-(MIN($J$14:$J$48)+MAX($J$14:$J$48))/2 -> -0.3 | M24: =K24-(INDEX($K$14:$K$48,MATCH(MIN($J$14:$J$48),$J$14:$J$48,0))+INDEX($K$14:$K$48,MATCH(MAX($J$14:$J$48),$J$14:$J$48,0)))/2 -> 0.0884 | O24: =(G24*COS(RADIANS($C$14))-H24*SIN(RADIANS($C$14)))*$B$14*1000 -> -8.23776 | P24: =(G24*SIN(RADIANS($C$14))+H24*COS(RADIANS($C$14)))*$B$14*1000 -> 21.71568 | R24: =(L24*COS(RADIANS($C$15))-M24*SIN(RADIANS($C$15)))*$B$15*1000 -> -65.058983 | S24: =(L24*SIN(RADIANS($C$15))+M24*COS(RADIANS($C$15)))*$B$15*1000 -> -15.762427 | U24: =(L24*COS(RADIANS($C$16))-M24*SIN(RADIANS($C$16)))*$B$16*1000 -> -59.565109 | V24: =(L24*SIN(RADIANS($C$16))+M24*COS(RADIANS($C$16)))*$B$16*1000 -> -4.1318421 | X24: =(L24*COS(RADIANS($C$17))-M24*SIN(RADIANS($C$17)))*$B$17*1000 -> -49.687406 | Y24: =(L24*SIN(RADIANS($C$17))+M24*COS(RADIANS($C$17)))*$B$17*1000 -> 1.673471 | AA24: =(L24*COS(RADIANS($C$18))-M24*SIN(RADIANS($C$18)))*$B$18*1000 -> -41.377277 | AB24: =(L24*SIN(RADIANS($C$18))+M24*COS(RADIANS($C$18)))*$B$18*1000 -> 4.1564804 | AD24: =(L24*COS(RADIANS($C$19))-M24*SIN(RADIANS($C$19)))*$B$19*1000 -> -35.024325 | AE24: =(L24*SIN(RADIANS($C$19))+M24*COS(RADIANS($C$19)))*$B$19*1000 -> 5.1404357 | AG24: =(L24*COS(RADIANS($C$20))-M24*SIN(RADIANS($C$20)))*$B$20*1000 -> -30.18622 | AH24: =(L24*SIN(RADIANS($C$20))+M24*COS(RADIANS($C$20)))*$B$20*1000 -> 5.4520678 | AJ24: =(L24*COS(RADIANS($C$21))-M24*SIN(RADIANS($C$21)))*$B$21*1000 -> -26.438946 | AK24: =(L24*SIN(RADIANS($C$21))+M24*COS(RADIANS($C$21)))*$B$21*1000 -> 5.4561077 | AM24: =(L24*COS(RADIANS($C$22))-M24*SIN(RADIANS($C$22)))*$B$22*1000 -> -23.475683 | AN24: =(L24*SIN(RADIANS($C$22))+M24*COS(RADIANS($C$22)))*$B$22*1000 -> 5.3193128 | AP24: =(L24*COS(RADIANS($C$23))-M24*SIN(RADIANS($C$23)))*$B$23*1000 -> -21.085216 | AQ24: =(L24*SIN(RADIANS($C$23))+M24*COS(RADIANS($C$23)))*$B$23*1000 -> 5.1210631 | AS24: =(L24*COS(RADIANS($C$24))-M24*SIN(RADIANS($C$24)))*$B$24*1000 -> -21.085216 | AT24: =(L24*SIN(RADIANS($C$24))+M24*COS(RADIANS($C$24)))*$B$24*1000 -> 5.1210631 | AV24: =(L24*COS(RADIANS($C$25))-M24*SIN(RADIANS($C$25)))*$B$25*1000 -> 0 | AW24: =(L24*SIN(RADIANS($C$25))+M24*COS(RADIANS($C$25)))*$B$25*1000 -> 0 | AY24: =(L24*COS(RADIANS($C$26))-M24*SIN(RADIANS($C$26)))*$B$26*1000 -> 0 | AZ24: =(L24*SIN(RADIANS($C$26))+M24*COS(RADIANS($C$26)))*$B$26*1000 -> 0 | BB24: =(L24*COS(RADIANS($C$27))-M24*SIN(RADIANS($C$27)))*$B$27*1000 -> 0 | BC24: =(L24*SIN(RADIANS($C$27))+M24*COS(RADIANS($C$27)))*$B$27*1000 -> 0 | BE24: =(L24*COS(RADIANS($C$28))-M24*SIN(RADIANS($C$28)))*$B$28*1000 -> 0 | BF24: =(L24*SIN(RADIANS($C$28))+M24*COS(RADIANS($C$28)))*$B$28*1000 -> 0 | BH24: =(L24*COS(RADIANS($C$29))-M24*SIN(RADIANS($C$29)))*$B$29*1000 -> 0 | BI24: =(L24*SIN(RADIANS($C$29))+M24*COS(RADIANS($C$29)))*$B$29*1000 -> 0 | BK24: =(L24*COS(RADIANS($C$30))-M24*SIN(RADIANS($C$30)))*$B$30*1000 -> 0 | BL24: =(L24*SIN(RADIANS($C$30))+M24*COS(RADIANS($C$30)))*$B$30*1000 -> 0 | BN24: =(L24*COS(RADIANS($C$31))-M24*SIN(RADIANS($C$31)))*$B$31*1000 -> 0 | BO24: =(L24*SIN(RADIANS($C$31))+M24*COS(RADIANS($C$31)))*$B$31*1000 -> 0 | BQ24: =(L24*COS(RADIANS($C$32))-M24*SIN(RADIANS($C$32)))*$B$32*1000 -> 0 | BR24: =(L24*SIN(RADIANS($C$32))+M24*COS(RADIANS($C$32)))*$B$32*1000 -> 0 | BT24: =(L24*COS(RADIANS($C$33))-M24*SIN(RADIANS($C$33)))*$B$33*1000 -> 0 | BU24: =(L24*SIN(RADIANS($C$33))+M24*COS(RADIANS($C$33)))*$B$33*1000 -> 0
E25: 0.24248 | F25: 0.42858 | G25: =E25-(MIN($E$14:$E$46)+MAX($J$14:$J$48))/2 -> -0.25813 | H25: =F25-(INDEX($F$14:$F$48,MATCH(MIN($E$14:$E$48),$E$14:$E$48,0))+INDEX($F$14:$F$48,MATCH(MAX($E$14:$E$48),$E$14:$E$48,0)))/2 -> 0.41114 | J25: 0.15 | K25: 0.0852 | L25: =J25-(MIN($J$14:$J$48)+MAX($J$14:$J$48))/2 -> -0.35 | M25: =K25-(INDEX($K$14:$K$48,MATCH(MIN($J$14:$J$48),$J$14:$J$48,0))+INDEX($K$14:$K$48,MATCH(MAX($J$14:$J$48),$J$14:$J$48,0)))/2 -> 0.0844 | O25: =(G25*COS(RADIANS($C$14))-H25*SIN(RADIANS($C$14)))*$B$14*1000 -> -12.39024 | P25: =(G25*SIN(RADIANS($C$14))+H25*COS(RADIANS($C$14)))*$B$14*1000 -> 19.73472 | R25: =(L25*COS(RADIANS($C$15))-M25*SIN(RADIANS($C$15)))*$B$15*1000 -> -73.895041 | S25: =(L25*SIN(RADIANS($C$15))+M25*COS(RADIANS($C$15)))*$B$15*1000 -> -21.860643 | U25: =(L25*COS(RADIANS($C$16))-M25*SIN(RADIANS($C$16)))*$B$16*1000 -> -68.246777 | V25: =(L25*SIN(RADIANS($C$16))+M25*COS(RADIANS($C$16)))*$B$16*1000 -> -8.1728818 | X25: =(L25*COS(RADIANS($C$17))-M25*SIN(RADIANS($C$17)))*$B$17*1000 -> -57.22357 | Y25: =(L25*SIN(RADIANS($C$17))+M25*COS(RADIANS($C$17)))*$B$17*1000 -> -0.93077213 | AA25: =(L25*COS(RADIANS($C$18))-M25*SIN(RADIANS($C$18)))*$B$18*1000 -> -47.811775 | AB25: =(L25*SIN(RADIANS($C$18))+M25*COS(RADIANS($C$18)))*$B$18*1000 -> 2.4014981 | AD25: =(L25*COS(RADIANS($C$19))-M25*SIN(RADIANS($C$19)))*$B$19*1000 -> -40.564088 | AE25: =(L25*SIN(RADIANS($C$19))+M25*COS(RADIANS($C$19)))*$B$19*1000 -> 3.8978004 | AG25: =(L25*COS(RADIANS($C$20))-M25*SIN(RADIANS($C$20)))*$B$20*1000 -> -35.019448 | AH25: =(L25*SIN(RADIANS($C$20))+M25*COS(RADIANS($C$20)))*$B$20*1000 -> 4.5340716 | AJ25: =(L25*COS(RADIANS($C$21))-M25*SIN(RADIANS($C$21)))*$B$21*1000 -> -30.711303 | AK25: =(L25*SIN(RADIANS($C$21))+M25*COS(RADIANS($C$21)))*$B$21*1000 -> 4.7540185 | AM25: =(L25*COS(RADIANS($C$22))-M25*SIN(RADIANS($C$22)))*$B$22*1000 -> -27.296472 | AN25: =(L25*SIN(RADIANS($C$22))+M25*COS(RADIANS($C$22)))*$B$22*1000 -> 4.7669967 | AP25: =(L25*COS(RADIANS($C$23))-M25*SIN(RADIANS($C$23)))*$B$23*1000 -> -24.536675 | AQ25: =(L25*SIN(RADIANS($C$23))+M25*COS(RADIANS($C$23)))*$B$23*1000 -> 4.6764076 | AS25: =(L25*COS(RADIANS($C$24))-M25*SIN(RADIANS($C$24)))*$B$24*1000 -> -24.536675 | AT25: =(L25*SIN(RADIANS($C$24))+M25*COS(RADIANS($C$24)))*$B$24*1000 -> 4.6764076 | AV25: =(L25*COS(RADIANS($C$25))-M25*SIN(RADIANS($C$25)))*$B$25*1000 -> 0 | AW25: =(L25*SIN(RADIANS($C$25))+M25*COS(RADIANS($C$25)))*$B$25*1000 -> 0 | AY25: =(L25*COS(RADIANS($C$26))-M25*SIN(RADIANS($C$26)))*$B$26*1000 -> 0 | AZ25: =(L25*SIN(RADIANS($C$26))+M25*COS(RADIANS($C$26)))*$B$26*1000 -> 0 | BB25: =(L25*COS(RADIANS($C$27))-M25*SIN(RADIANS($C$27)))*$B$27*1000 -> 0 | BC25: =(L25*SIN(RADIANS($C$27))+M25*COS(RADIANS($C$27)))*$B$27*1000 -> 0 | BE25: =(L25*COS(RADIANS($C$28))-M25*SIN(RADIANS($C$28)))*$B$28*1000 -> 0 | BF25: =(L25*SIN(RADIANS($C$28))+M25*COS(RADIANS($C$28)))*$B$28*1000 -> 0 | BH25: =(L25*COS(RADIANS($C$29))-M25*SIN(RADIANS($C$29)))*$B$29*1000 -> 0 | BI25: =(L25*SIN(RADIANS($C$29))+M25*COS(RADIANS($C$29)))*$B$29*1000 -> 0 | BK25: =(L25*COS(RADIANS($C$30))-M25*SIN(RADIANS($C$30)))*$B$30*1000 -> 0 | BL25: =(L25*SIN(RADIANS($C$30))+M25*COS(RADIANS($C$30)))*$B$30*1000 -> 0 | BN25: =(L25*COS(RADIANS($C$31))-M25*SIN(RADIANS($C$31)))*$B$31*1000 -> 0 | BO25: =(L25*SIN(RADIANS($C$31))+M25*COS(RADIANS($C$31)))*$B$31*1000 -> 0 | BQ25: =(L25*COS(RADIANS($C$32))-M25*SIN(RADIANS($C$32)))*$B$32*1000 -> 0 | BR25: =(L25*SIN(RADIANS($C$32))+M25*COS(RADIANS($C$32)))*$B$32*1000 -> 0 | BT25: =(L25*COS(RADIANS($C$33))-M25*SIN(RADIANS($C$33)))*$B$33*1000 -> 0 | BU25: =(L25*SIN(RADIANS($C$33))+M25*COS(RADIANS($C$33)))*$B$33*1000 -> 0
E26: 0.16543 | F26: 0.37157 | G26: =E26-(MIN($E$14:$E$46)+MAX($J$14:$J$48))/2 -> -0.33518 | H26: =F26-(INDEX($F$14:$F$48,MATCH(MIN($E$14:$E$48),$E$14:$E$48,0))+INDEX($F$14:$F$48,MATCH(MAX($E$14:$E$48),$E$14:$E$48,0)))/2 -> 0.35413 | J26: 0.1 | K26: 0.0764 | L26: =J26-(MIN($J$14:$J$48)+MAX($J$14:$J$48))/2 -> -0.4 | M26: =K26-(INDEX($K$14:$K$48,MATCH(MIN($J$14:$J$48),$J$14:$J$48,0))+INDEX($K$14:$K$48,MATCH(MAX($J$14:$J$48),$J$14:$J$48,0)))/2 -> 0.0756 | O26: =(G26*COS(RADIANS($C$14))-H26*SIN(RADIANS($C$14)))*$B$14*1000 -> -16.08864 | P26: =(G26*SIN(RADIANS($C$14))+H26*COS(RADIANS($C$14)))*$B$14*1000 -> 16.99824 | R26: =(L26*COS(RADIANS($C$15))-M26*SIN(RADIANS($C$15)))*$B$15*1000 -> -82.216821 | S26: =(L26*SIN(RADIANS($C$15))+M26*COS(RADIANS($C$15)))*$B$15*1000 -> -28.848263 | U26: =(L26*COS(RADIANS($C$16))-M26*SIN(RADIANS($C$16)))*$B$16*1000 -> -76.609222 | V26: =(L26*SIN(RADIANS($C$16))+M26*COS(RADIANS($C$16)))*$B$16*1000 -> -13.072899 | X26: =(L26*COS(RADIANS($C$17))-M26*SIN(RADIANS($C$17)))*$B$17*1000 -> -64.568825 | Y26: =(L26*SIN(RADIANS($C$17))+M26*COS(RADIANS($C$17)))*$B$17*1000 -> -4.2737596 | AA26: =(L26*COS(RADIANS($C$18))-M26*SIN(RADIANS($C$18)))*$B$18*1000 -> -54.127969 | AB26: =(L26*SIN(RADIANS($C$18))+M26*COS(RADIANS($C$18)))*$B$18*1000 -> 0.019339643 | AD26: =(L26*COS(RADIANS($C$19))-M26*SIN(RADIANS($C$19)))*$B$19*1000 -> -46.027592 | AE26: =(L26*SIN(RADIANS($C$19))+M26*COS(RADIANS($C$19)))*$B$19*1000 -> 2.1172471 | AG26: =(L26*COS(RADIANS($C$20))-M26*SIN(RADIANS($C$20)))*$B$20*1000 -> -39.801992 | AH26: =(L26*SIN(RADIANS($C$20))+M26*COS(RADIANS($C$20)))*$B$20*1000 -> 3.1480308 | AJ26: =(L26*COS(RADIANS($C$21))-M26*SIN(RADIANS($C$21)))*$B$21*1000 -> -34.949291 | AK26: =(L26*SIN(RADIANS($C$21))+M26*COS(RADIANS($C$21)))*$B$21*1000 -> 3.6390336 | AM26: =(L26*COS(RADIANS($C$22))-M26*SIN(RADIANS($C$22)))*$B$22*1000 -> -31.093733 | AN26: =(L26*SIN(RADIANS($C$22))+M26*COS(RADIANS($C$22)))*$B$22*1000 -> 3.8460027 | AP26: =(L26*COS(RADIANS($C$23))-M26*SIN(RADIANS($C$23)))*$B$23*1000 -> -27.972056 | AQ26: =(L26*SIN(RADIANS($C$23))+M26*COS(RADIANS($C$23)))*$B$23*1000 -> 3.899126 | AS26: =(L26*COS(RADIANS($C$24))-M26*SIN(RADIANS($C$24)))*$B$24*1000 -> -27.972056 | AT26: =(L26*SIN(RADIANS($C$24))+M26*COS(RADIANS($C$24)))*$B$24*1000 -> 3.899126 | AV26: =(L26*COS(RADIANS($C$25))-M26*SIN(RADIANS($C$25)))*$B$25*1000 -> 0 | AW26: =(L26*SIN(RADIANS($C$25))+M26*COS(RADIANS($C$25)))*$B$25*1000 -> 0 | AY26: =(L26*COS(RADIANS($C$26))-M26*SIN(RADIANS($C$26)))*$B$26*1000 -> 0 | AZ26: =(L26*SIN(RADIANS($C$26))+M26*COS(RADIANS($C$26)))*$B$26*1000 -> 0 | BB26: =(L26*COS(RADIANS($C$27))-M26*SIN(RADIANS($C$27)))*$B$27*1000 -> 0 | BC26: =(L26*SIN(RADIANS($C$27))+M26*COS(RADIANS($C$27)))*$B$27*1000 -> 0 | BE26: =(L26*COS(RADIANS($C$28))-M26*SIN(RADIANS($C$28)))*$B$28*1000 -> 0 | BF26: =(L26*SIN(RADIANS($C$28))+M26*COS(RADIANS($C$28)))*$B$28*1000 -> 0 | BH26: =(L26*COS(RADIANS($C$29))-M26*SIN(RADIANS($C$29)))*$B$29*1000 -> 0 | BI26: =(L26*SIN(RADIANS($C$29))+M26*COS(RADIANS($C$29)))*$B$29*1000 -> 0 | BK26: =(L26*COS(RADIANS($C$30))-M26*SIN(RADIANS($C$30)))*$B$30*1000 -> 0 | BL26: =(L26*SIN(RADIANS($C$30))+M26*COS(RADIANS($C$30)))*$B$30*1000 -> 0 | BN26: =(L26*COS(RADIANS($C$31))-M26*SIN(RADIANS($C$31)))*$B$31*1000 -> 0 | BO26: =(L26*SIN(RADIANS($C$31))+M26*COS(RADIANS($C$31)))*$B$31*1000 -> 0 | BQ26: =(L26*COS(RADIANS($C$32))-M26*SIN(RADIANS($C$32)))*$B$32*1000 -> 0 | BR26: =(L26*SIN(RADIANS($C$32))+M26*COS(RADIANS($C$32)))*$B$32*1000 -> 0 | BT26: =(L26*COS(RADIANS($C$33))-M26*SIN(RADIANS($C$33)))*$B$33*1000 -> 0 | BU26: =(L26*SIN(RADIANS($C$33))+M26*COS(RADIANS($C$33)))*$B$33*1000 -> 0
E27: 0.10068 | F27: 0.30091 | G27: =E27-(MIN($E$14:$E$46)+MAX($J$14:$J$48))/2 -> -0.39993 | H27: =F27-(INDEX($F$14:$F$48,MATCH(MIN($E$14:$E$48),$E$14:$E$48,0))+INDEX($F$14:$F$48,MATCH(MAX($E$14:$E$48),$E$14:$E$48,0)))/2 -> 0.28347 | J27: 0.075 | K27: 0.069 | L27: =J27-(MIN($J$14:$J$48)+MAX($J$14:$J$48))/2 -> -0.425 | M27: =K27-(INDEX($K$14:$K$48,MATCH(MIN($J$14:$J$48),$J$14:$J$48,0))+INDEX($K$14:$K$48,MATCH(MAX($J$14:$J$48),$J$14:$J$48,0)))/2 -> 0.0682 | O27: =(G27*COS(RADIANS($C$14))-H27*SIN(RADIANS($C$14)))*$B$14*1000 -> -19.19664 | P27: =(G27*SIN(RADIANS($C$14))+H27*COS(RADIANS($C$14)))*$B$14*1000 -> 13.60656 | R27: =(L27*COS(RADIANS($C$15))-M27*SIN(RADIANS($C$15)))*$B$15*1000 -> -86.056289 | S27: =(L27*SIN(RADIANS($C$15))+M27*COS(RADIANS($C$15)))*$B$15*1000 -> -32.89795 | U27: =(L27*COS(RADIANS($C$16))-M27*SIN(RADIANS($C$16)))*$B$16*1000 -> -80.590932 | V27: =(L27*SIN(RADIANS($C$16))+M27*COS(RADIANS($C$16)))*$B$16*1000 -> -16.059769 | X27: =(L27*COS(RADIANS($C$17))-M27*SIN(RADIANS($C$17)))*$B$17*1000 -> -68.122136 | Y27: =(L27*SIN(RADIANS($C$17))+M27*COS(RADIANS($C$17)))*$B$17*1000 -> -6.4069685 | AA27: =(L27*COS(RADIANS($C$18))-M27*SIN(RADIANS($C$18)))*$B$18*1000 -> -57.212125 | AB27: =(L27*SIN(RADIANS($C$18))+M27*COS(RADIANS($C$18)))*$B$18*1000 -> -1.5637247 | AD27: =(L27*COS(RADIANS($C$19))-M27*SIN(RADIANS($C$19)))*$B$19*1000 -> -48.711681 | AE27: =(L27*SIN(RADIANS($C$19))+M27*COS(RADIANS($C$19)))*$B$19*1000 -> 0.89077161 | AG27: =(L27*COS(RADIANS($C$20))-M27*SIN(RADIANS($C$20)))*$B$20*1000 -> -42.161586 | AH27: =(L27*SIN(RADIANS($C$20))+M27*COS(RADIANS($C$20)))*$B$20*1000 -> 2.1624825 | AJ27: =(L27*COS(RADIANS($C$21))-M27*SIN(RADIANS($C$21)))*$B$21*1000 -> -37.046804 | AK27: =(L27*SIN(RADIANS($C$21))+M27*COS(RADIANS($C$21)))*$B$21*1000 -> 2.8234812 | AM27: =(L27*COS(RADIANS($C$22))-M27*SIN(RADIANS($C$22)))*$B$22*1000 -> -32.977658 | AN27: =(L27*SIN(RADIANS($C$22))+M27*COS(RADIANS($C$22)))*$B$22*1000 -> 3.1550819 | AP27: =(L27*COS(RADIANS($C$23))-M27*SIN(RADIANS($C$23)))*$B$23*1000 -> -29.679699 | AQ27: =(L27*SIN(RADIANS($C$23))+M27*COS(RADIANS($C$23)))*$B$23*1000 -> 3.3025939 | AS27: =(L27*COS(RADIANS($C$24))-M27*SIN(RADIANS($C$24)))*$B$24*1000 -> -29.679699 | AT27: =(L27*SIN(RADIANS($C$24))+M27*COS(RADIANS($C$24)))*$B$24*1000 -> 3.3025939 | AV27: =(L27*COS(RADIANS($C$25))-M27*SIN(RADIANS($C$25)))*$B$25*1000 -> 0 | AW27: =(L27*SIN(RADIANS($C$25))+M27*COS(RADIANS($C$25)))*$B$25*1000 -> 0 | AY27: =(L27*COS(RADIANS($C$26))-M27*SIN(RADIANS($C$26)))*$B$26*1000 -> 0 | AZ27: =(L27*SIN(RADIANS($C$26))+M27*COS(RADIANS($C$26)))*$B$26*1000 -> 0 | BB27: =(L27*COS(RADIANS($C$27))-M27*SIN(RADIANS($C$27)))*$B$27*1000 -> 0 | BC27: =(L27*SIN(RADIANS($C$27))+M27*COS(RADIANS($C$27)))*$B$27*1000 -> 0 | BE27: =(L27*COS(RADIANS($C$28))-M27*SIN(RADIANS($C$28)))*$B$28*1000 -> 0 | BF27: =(L27*SIN(RADIANS($C$28))+M27*COS(RADIANS($C$28)))*$B$28*1000 -> 0 | BH27: =(L27*COS(RADIANS($C$29))-M27*SIN(RADIANS($C$29)))*$B$29*1000 -> 0 | BI27: =(L27*SIN(RADIANS($C$29))+M27*COS(RADIANS($C$29)))*$B$29*1000 -> 0 | BK27: =(L27*COS(RADIANS($C$30))-M27*SIN(RADIANS($C$30)))*$B$30*1000 -> 0 | BL27: =(L27*SIN(RADIANS($C$30))+M27*COS(RADIANS($C$30)))*$B$30*1000 -> 0 | BN27: =(L27*COS(RADIANS($C$31))-M27*SIN(RADIANS($C$31)))*$B$31*1000 -> 0 | BO27: =(L27*SIN(RADIANS($C$31))+M27*COS(RADIANS($C$31)))*$B$31*1000 -> 0 | BQ27: =(L27*COS(RADIANS($C$32))-M27*SIN(RADIANS($C$32)))*$B$32*1000 -> 0 | BR27: =(L27*SIN(RADIANS($C$32))+M27*COS(RADIANS($C$32)))*$B$32*1000 -> 0 | BT27: =(L27*COS(RADIANS($C$33))-M27*SIN(RADIANS($C$33)))*$B$33*1000 -> 0 | BU27: =(L27*SIN(RADIANS($C$33))+M27*COS(RADIANS($C$33)))*$B$33*1000 -> 0
E28: 0.0506 | F28: 0.21919 | G28: =E28-(MIN($E$14:$E$46)+MAX($J$14:$J$48))/2 -> -0.45001 | H28: =F28-(INDEX($F$14:$F$48,MATCH(MIN($E$14:$E$48),$E$14:$E$48,0))+INDEX($F$14:$F$48,MATCH(MAX($E$14:$E$48),$E$14:$E$48,0)))/2 -> 0.20175 | J28: 0.05 | K28: 0.0589 | L28: =J28-(MIN($J$14:$J$48)+MAX($J$14:$J$48))/2 -> -0.45 | M28: =K28-(INDEX($K$14:$K$48,MATCH(MIN($J$14:$J$48),$J$14:$J$48,0))+INDEX($K$14:$K$48,MATCH(MAX($J$14:$J$48),$J$14:$J$48,0)))/2 -> 0.0581 | O28: =(G28*COS(RADIANS($C$14))-H28*SIN(RADIANS($C$14)))*$B$14*1000 -> -21.60048 | P28: =(G28*SIN(RADIANS($C$14))+H28*COS(RADIANS($C$14)))*$B$14*1000 -> 9.684 | R28: =(L28*COS(RADIANS($C$15))-M28*SIN(RADIANS($C$15)))*$B$15*1000 -> -89.606476 | S28: =(L28*SIN(RADIANS($C$15))+M28*COS(RADIANS($C$15)))*$B$15*1000 -> -37.447926 | U28: =(L28*COS(RADIANS($C$16))-M28*SIN(RADIANS($C$16)))*$B$16*1000 -> -84.393079 | V28: =(L28*SIN(RADIANS($C$16))+M28*COS(RADIANS($C$16)))*$B$16*1000 -> -19.529814 | X28: =(L28*COS(RADIANS($C$17))-M28*SIN(RADIANS($C$17)))*$B$17*1000 -> -71.568061 | Y28: =(L28*SIN(RADIANS($C$17))+M28*COS(RADIANS($C$17)))*$B$17*1000 -> -8.9557211 | AA28: =(L28*COS(RADIANS($C$18))-M28*SIN(RADIANS($C$18)))*$B$18*1000 -> -60.229736 | AB28: =(L28*SIN(RADIANS($C$18))+M28*COS(RADIANS($C$18)))*$B$18*1000 -> -3.4995755 | AD28: =(L28*COS(RADIANS($C$19))-M28*SIN(RADIANS($C$19)))*$B$19*1000 -> -51.352875 | AE28: =(L28*SIN(RADIANS($C$19))+M28*COS(RADIANS($C$19)))*$B$19*1000 -> -0.63828275 | AG28: =(L28*COS(RADIANS($C$20))-M28*SIN(RADIANS($C$20)))*$B$20*1000 -> -44.492671 | AH28: =(L28*SIN(RADIANS($C$20))+M28*COS(RADIANS($C$20)))*$B$20*1000 -> 0.91365915 | AJ28: =(L28*COS(RADIANS($C$21))-M28*SIN(RADIANS($C$21)))*$B$21*1000 -> -39.124985 | AK28: =(L28*SIN(RADIANS($C$21))+M28*COS(RADIANS($C$21)))*$B$21*1000 -> 1.7756751 | AM28: =(L28*COS(RADIANS($C$22))-M28*SIN(RADIANS($C$22)))*$B$22*1000 -> -34.848349 | AN28: =(L28*SIN(RADIANS($C$22))+M28*COS(RADIANS($C$22)))*$B$22*1000 -> 2.2567798 | AP28: =(L28*COS(RADIANS($C$23))-M28*SIN(RADIANS($C$23)))*$B$23*1000 -> -31.378299 | AQ28: =(L28*SIN(RADIANS($C$23))+M28*COS(RADIANS($C$23)))*$B$23*1000 -> 2.5189595 | AS28: =(L28*COS(RADIANS($C$24))-M28*SIN(RADIANS($C$24)))*$B$24*1000 -> -31.378299 | AT28: =(L28*SIN(RADIANS($C$24))+M28*COS(RADIANS($C$24)))*$B$24*1000 -> 2.5189595 | AV28: =(L28*COS(RADIANS($C$25))-M28*SIN(RADIANS($C$25)))*$B$25*1000 -> 0 | AW28: =(L28*SIN(RADIANS($C$25))+M28*COS(RADIANS($C$25)))*$B$25*1000 -> 0 | AY28: =(L28*COS(RADIANS($C$26))-M28*SIN(RADIANS($C$26)))*$B$26*1000 -> 0 | AZ28: =(L28*SIN(RADIANS($C$26))+M28*COS(RADIANS($C$26)))*$B$26*1000 -> 0 | BB28: =(L28*COS(RADIANS($C$27))-M28*SIN(RADIANS($C$27)))*$B$27*1000 -> 0 | BC28: =(L28*SIN(RADIANS($C$27))+M28*COS(RADIANS($C$27)))*$B$27*1000 -> 0 | BE28: =(L28*COS(RADIANS($C$28))-M28*SIN(RADIANS($C$28)))*$B$28*1000 -> 0 | BF28: =(L28*SIN(RADIANS($C$28))+M28*COS(RADIANS($C$28)))*$B$28*1000 -> 0 | BH28: =(L28*COS(RADIANS($C$29))-M28*SIN(RADIANS($C$29)))*$B$29*1000 -> 0 | BI28: =(L28*SIN(RADIANS($C$29))+M28*COS(RADIANS($C$29)))*$B$29*1000 -> 0 | BK28: =(L28*COS(RADIANS($C$30))-M28*SIN(RADIANS($C$30)))*$B$30*1000 -> 0 | BL28: =(L28*SIN(RADIANS($C$30))+M28*COS(RADIANS($C$30)))*$B$30*1000 -> 0 | BN28: =(L28*COS(RADIANS($C$31))-M28*SIN(RADIANS($C$31)))*$B$31*1000 -> 0 | BO28: =(L28*SIN(RADIANS($C$31))+M28*COS(RADIANS($C$31)))*$B$31*1000 -> 0 | BQ28: =(L28*COS(RADIANS($C$32))-M28*SIN(RADIANS($C$32)))*$B$32*1000 -> 0 | BR28: =(L28*SIN(RADIANS($C$32))+M28*COS(RADIANS($C$32)))*$B$32*1000 -> 0 | BT28: =(L28*COS(RADIANS($C$33))-M28*SIN(RADIANS($C$33)))*$B$33*1000 -> 0 | BU28: =(L28*SIN(RADIANS($C$33))+M28*COS(RADIANS($C$33)))*$B$33*1000 -> 0
